Workbook

Sheet Rapport d'analyse
A6: Analyse NBA 2024-2025 – Mission Les Pionniers
C8: Projet 2 – Parcours Business Intelligence Analyst – OpenClassrooms
A10: 24 octobre 2025
A14: Henrique DA COSTA

Sheet Contexte_Objectif
A1: Contexte et objectifs
A3: Le club de basket Les Pionniers, structure semi-professionnelle, ambitionne de monter en division supérieure.
A5: Pour atteindre cet objectif, l’équipe souhaite s’appuyer sur une approche plus analytique de la performance
A6: sportive, inspirée des pratiques des grands clubs de la NBA dans les cinq prochaines saisons.
A8: Dans ce cadre, le club a mandaté notre Entreprise de Services Numériques (ESN) pour réaliser une analyse
A9: exploratoire des statistiques de la saison régulière NBA 2024/2025.
A11: L’objectif est double :
A13: 1️⃣ Identifier les facteurs clés de performance qui expliquent la réussite individuelle et collective des joueurs
A14: NBA ;
A15: 2️⃣ Déterminer les leviers d’amélioration que Les Pionniers pourraient adapter localement, tant sur le plan de
A16: l’entraînement, du recrutement, que du style de jeu.
A18: Cette première mission s’inscrit dans une démarche de data-driven performance, visant à utiliser les données
... A21: rebonds, efficacité, etc.), enrichies d’indicateurs complémentaires construits pour affiner l’analyse :
B23: Efficacité au tir (EFG%, TS%),
B24: Création et maîtrise du ballon (AST/TOV, AST/Min),
B25: Impact défensif (REB/Min, BLK/Min, STL/Min).
A27: À travers cette étude, le but est de produire une analyse lisible, visuelle et exploitable, permettant au staff
A28: technique des Pionniers d’orienter ses choix stratégiques et de définir des profils de joueurs cohérents avec ses
A29: ambitions sportives.

Sheet Méthodologie
A1: Méthodologie
A4: L’analyse a été conduite selon une démarche structurée en plusieurs étapes, inspirée des bonnes pratiques de la
A5: data analysis appliquée au sport de haut niveau.
A7: L’objectif était de garantir la fiabilité des données, la pertinence des indicateurs produits, et la lisibilité
A8: des résultats pour un public non technique.
A11: Préparation et nettoyage du jeu de données
A13: Le jeu de données utilisé correspond aux statistiques complètes de la saison régulière NBA 2024/2025.
A14: Une première étape a consisté à :
B16: Supprimer les lignes incomplètes ou comportant des valeurs manquantes ;
B17: Uniformiser les formats (décimales, pourcentages, noms d’équipes) ;
B18: Appliquer des filtres de cohérence pour ne conserver que les joueurs significatifs :
C19: => GP (Games Played) ≥ 30,
C20: => Min (Minutes jouées) ≥ 300.
A22: Ces traitements visent à éliminer les biais statistiques liés aux joueurs peu utilisés ou aux échantillons trop faibles.
A25: Enrichissement et création d’indicateurs
A27: Afin d’aller au-delà des données brutes, plusieurs indicateurs calculés ont été ajoutés pour analyser les
A28: dimensions clés de la performance (Cf. Dictionnaire de donnée enrichi ) :
A30: => Productivité offensive : PTS/Min, PTS_tot, FGA_tot ;
A31: => Efficacité au tir : EFG% = (FG + 0,5×3P)/FGA, TS% = PTS/(2×(FGA+0,44×FTA)) ;
A32: => Création et maîtrise : AST/TOV, AST/Min ;
A33: => Impact défensif : OREB/Min, DREB/Min, STL/Min, BLK/Min ;
A34: => Indices normalisés (FGA_norm, PTS_norm) pour faciliter la comparaison inter-joueurs.
A37: Des mises en forme conditionnelles ont ensuite été intégrées dans le tableau de données enrichi afin de
A38: visualiser instantanément les valeurs extrêmes et les tendances fortes (du rouge au vert pour les indicateurs de
A39: performance).
... A67: recrutement stratégique.

Sheet Données NBA enrichies
A1: Player | B1: Team | C1: Age | D1: GP | E1: W | F1: L | G1: Min | H1: PTS | I1: FGM | J1: FGA | K1: FG% | L1: 0.625 | M1: 3PA | N1: 3P% | O1: FTM | P1: FTA | Q1: FT% | R1: OREB | S1: DREB | T1: REB | U1: AST | V1: TOV | W1: STL | X1: BLK | Y1: PF | Z1: FP | AA1: DD2 | AB1: TD3 | AC1: ="+/-" -> +/- | AD1: OFFRTG | AE1: DEFRTG | AF1: NETRTG | AG1: AST% | AH1: AST/TO | AI1: AST RATIO | AJ1: OREB% | AK1: DREB% | AL1: REB% | AM1: TO RATIO | AN1: EFG% | AO1: TS% | AP1: USG% | AQ1: PACE | AR1: PIE | AS1: POSS | AT1: PTS_pg | AU1: AST_pg | AV1: REB_pg | AW1: OREB_pg | AX1: DREB_pg | AY1: STL_pg | AZ1: BLK_pg | BA1: TOV_pg | BB1: PTS_pg/Min | BC1: AST_pg/TOV_pg | BD1: STL_pg/Min | BE1: BLK_pg/Min | BF1: OREB_pg/Min | BG1: DREB_pg/Min | BH1: Classe_Min | BI1: Classe_Age | BJ1: EFG%_corr | BK1: TS%_corr | BL1: FGA_norm | BM1: Filtre joueur | BN1: PTS_pg_Norm | BO1: Min_tot | BP1: AST/Min | BQ1: AST/TOV | BR1: REB_pg/Min
A2: Shai Gilgeous-Alexander | B2: OKC | C2: 26 | D2: 76 | E2: 63 | F2: 13 | G2: 34.2 | H2: 2485 | I2: 859 | J2: 1657 | K2: 51.9 | L2: 160 | M2: 433 | N2: 37.5 | O2: 600 | P2: 669 | Q2: 89.8 | R2: 68 | S2: 312 | T2: 380 | U2: 486 | V2: 182 | W2: 129 | X2: 76 | Y2: 167 | Z2: 4112 | AA2: 6 | AB2: 0 | AC2: 12.1 | AD2: 122.4 | AE2: 105.7 | AF2: 16.7 | AG2: 29.9 | AH2: 2.66 | AI2: 18.7 | AJ2: 2.5 | AK2: 11.2 | AL2: 6.9 | AM2: 7 | AN2: 56.9 | AO2: 63.7 | AP2: 33.6 | AQ2: 101.91 | AR2: 19.9 | AS2: 5514 | AT2: =H2/D2 -> 32.697368 | AU2: =U2/D2 -> 6.3947368 | AV2: =T2/D2 -> 5 | AW2: =R2/D2 -> 0.89473684 | AX2: =S2/D2 -> 4.1052632 | AY2: =W2/D2 -> 1.6973684 | AZ2: =X2/D2 -> 1 | BA2: =V2/D2 -> 2.3947368 | BB2: =IF(G2>0,AT2/G2,"") -> 0.9560634 | BC2: =IF(BA2>0,AU2/BA2,"") -> 2.6703297 | BD2: =IF(G2>0,AY2/G2,"") -> 0.049630656 | BE2: =IF(G2>0,AZ2/G2,"") -> 0.029239766 | BF2: =IF(G2>0,AW2/G2,"") -> 0.026161896 | BG2: =IF(G2>0,AX2/G2,"") -> 0.12003693 | BH2: =IF(G2<10,"<10 min",IF(G2<20,"10–19 min",IF(G2<30,"20–29 min",IF(G2<40,"30–39 min","40+ min")))) -> 30–39 min | BI2: =IF(C2<23,"18–22",IF(C2<28,"23–27",IF(C2<33,"28–32","33+"))) -> 23–27 | BJ2: =AN2/100 -> 0.569 | BK2: =AO2/100 -> 0.637 | BL2: =J2/(MAX($J$2:$J$570)) -> 1 | BM2: =IF(AND(G2>=30,J2>=500),"Conserver","Écarter") -> Conserver | BN2: =AT2/(MAX($AT$2:$AT$570)) -> 1 | BO2: =G2*D2 -> 2599.2 | BP2: =IF(BO2>0,U2/BO2,"") -> 0.18698061 | BQ2: =IF(V2>0,U2/V2,0) -> 2.6703297 | BR2: =IF(G2>0,AV2/G2,"") -> 0.14619883
A3: Giannis Antetokounmpo | B3: MIL | C3: 30 | D3: 67 | E3: 40 | F3: 27 | G3: 34.2 | H3: 2037 | I3: 791 | J3: 1320 | K3: 60.1 | L3: 13 | M3: 60 | N3: 22.2 | O3: 436 | P3: 710 | Q3: 61.7 | R3: 147 | S3: 650 | T3: 797 | U3: 436 | V3: 208 | W3: 60 | X3: 80 | Y3: 154 | Z3: 3846 | AA3: 55 | AB3: 11 | AC3: 5 | AD3: 118.9 | AE3: 111.7 | AF3: 7.2 | AG3: 33.9 | AH3: 2.1 | AI3: 19.2 | AJ3: 6.7 | AK3: 26.6 | AL3: 17.2 | AM3: 9.1 | AN3: 60.7 | AO3: 62.5 | AP3: 34.6 | AQ3: 100.18 | AR3: 21 | AS3: 4772 | AT3: =H3/D3 -> 30.402985 | AU3: =U3/D3 -> 6.5074627 | AV3: =T3/D3 -> 11.895522 | AW3: =R3/D3 -> 2.1940299 | AX3: =S3/D3 -> 9.7014925 | AY3: =W3/D3 -> 0.89552239 | AZ3: =X3/D3 -> 1.1940299 | BA3: =V3/D3 -> 3.1044776 | BB3: =IF(G3>0,AT3/G3,"") -> 0.88897617 | BC3: =IF(BA3>0,AU3/BA3,"") -> 2.0961538 | BD3: =IF(G3>0,AY3/G3,"") -> 0.026184865 | BE3: =IF(G3>0,AZ3/G3,"") -> 0.034913154 | BF3: =IF(G3>0,AW3/G3,"") -> 0.06415292 | BG3: =IF(G3>0,AX3/G3,"") -> 0.28366937 | BH3: =IF(G3<10,"<10 min",IF(G3<20,"10–19 min",IF(G3<30,"20–29 min",IF(G3<40,"30–39 min","40+ min")))) -> 30–39 min | BI3: =IF(C3<23,"18–22",IF(C3<28,"23–27",IF(C3<33,"28–32","33+"))) -> 28–32 | BJ3: =AN3/100 -> 0.607 | BK3: =AO3/100 -> 0.625 | BL3: =J3/(MAX($J$2:$J$570)) -> 0.7966204 | BM3: =IF(AND(G3>=30,J3>=500),"Conserver","Écarter") -> Conserver | BN3: =AT3/(MAX($AT$2:$AT$570)) -> 0.92982972 | BO3: =G3*D3 -> 2291.4 | BP3: =IF(BO3>0,U3/BO3,"") -> 0.19027669 | BQ3: =IF(V3>0,U3/V3,0) -> 2.0961538 | BR3: =IF(G3>0,AV3/G3,"") -> 0.34782229
A4: Nikola Jokić | B4: DEN | C4: 30 | D4: 70 | E4: 46 | F4: 24 | G4: 36.7 | H4: 2072 | I4: 784 | J4: 1365 | K4: 57.6 | L4: 140 | M4: 329 | N4: 41.7 | O4: 364 | P4: 448 | Q4: 80 | R4: 203 | S4: 693 | T4: 889 | U4: 714 | V4: 231 | W4: 126 | X4: 42 | Y4: 161 | Z4: 4501 | AA4: 59 | AB4: 34 | AC4: 8.5 | AD4: 125.6 | AE4: 115.1 | AF4: 10.5 | AG4: 39.8 | AH4: 3.11 | AI4: 28.7 | AJ4: 8.3 | AK4: 25.2 | AL4: 17.3 | AM4: 9.2 | AN4: 62.7 | AO4: 66.3 | AP4: 28.5 | AQ4: 101.99 | AR4: 20.6 | AS4: 5471 | AT4: =H4/D4 -> 29.6 | AU4: =U4/D4 -> 10.2 | AV4: =T4/D4 -> 12.7 | AW4: =R4/D4 -> 2.9 | AX4: =S4/D4 -> 9.9 | AY4: =W4/D4 -> 1.8 | AZ4: =X4/D4 -> 0.6 | BA4: =V4/D4 -> 3.3 | BB4: =IF(G4>0,AT4/G4,"") -> 0.80653951 | BC4: =IF(BA4>0,AU4/BA4,"") -> 3.0909091 | BD4: =IF(G4>0,AY4/G4,"") -> 0.049046322 | BE4: =IF(G4>0,AZ4/G4,"") -> 0.016348774 | BF4: =IF(G4>0,AW4/G4,"") -> 0.079019074 | BG4: =IF(G4>0,AX4/G4,"") -> 0.26975477 | BH4: =IF(G4<10,"<10 min",IF(G4<20,"10–19 min",IF(G4<30,"20–29 min",IF(G4<40,"30–39 min","40+ min")))) -> 30–39 min | BI4: =IF(C4<23,"18–22",IF(C4<28,"23–27",IF(C4<33,"28–32","33+"))) -> 28–32 | BJ4: =AN4/100 -> 0.627 | BK4: =AO4/100 -> 0.663 | BL4: =J4/(MAX($J$2:$J$570)) -> 0.82377791 | BM4: =IF(AND(G4>=30,J4>=500),"Conserver","Écarter") -> Conserver | BN4: =AT4/(MAX($AT$2:$AT$570)) -> 0.90527163 | BO4: =G4*D4 -> 2569 | BP4: =IF(BO4>0,U4/BO4,"") -> 0.27792916 | BQ4: =IF(V4>0,U4/V4,0) -> 3.0909091 | BR4: =IF(G4>0,AV4/G4,"") -> 0.34604905
A5: Luka Dončić | B5: LAL | C5: 26 | D5: 50 | E5: 31 | F5: 19 | G5: 35.4 | H5: 1410 | I5: 460 | J5: 1025 | K5: 45 | L5: 175 | M5: 480 | N5: 36.8 | O5: 310 | P5: 395 | Q5: 78.2 | R5: 40 | S5: 370 | T5: 410 | U5: 385 | V5: 180 | W5: 90 | X5: 20 | Y5: 125 | Z5: 2625 | AA5: 21 | AB5: 5 | AC5: 6.9 | AD5: 119.6 | AE5: 110.5 | AF5: 9.1 | AG5: 34.2 | AH5: 2.14 | AI5: 21.8 | AJ5: 2.3 | AK5: 19.8 | AL5: 11.2 | AM5: 10.2 | AN5: 53.6 | AO5: 58.7 | AP5: 32.8 | AQ5: 100.22 | AR5: 17 | AS5: 3696 | AT5: =H5/D5 -> 28.2 | AU5: =U5/D5 -> 7.7 | AV5: =T5/D5 -> 8.2 | AW5: =R5/D5 -> 0.8 | AX5: =S5/D5 -> 7.4 | AY5: =W5/D5 -> 1.8 | AZ5: =X5/D5 -> 0.4 | BA5: =V5/D5 -> 3.6 | BB5: =IF(G5>0,AT5/G5,"") -> 0.79661017 | BC5: =IF(BA5>0,AU5/BA5,"") -> 2.1388889 | BD5: =IF(G5>0,AY5/G5,"") -> 0.050847458 | BE5: =IF(G5>0,AZ5/G5,"") -> 0.011299435 | BF5: =IF(G5>0,AW5/G5,"") -> 0.02259887 | BG5: =IF(G5>0,AX5/G5,"") -> 0.20903955 | BH5: =IF(G5<10,"<10 min",IF(G5<20,"10–19 min",IF(G5<30,"20–29 min",IF(G5<40,"30–39 min","40+ min")))) -> 30–39 min | BI5: =IF(C5<23,"18–22",IF(C5<28,"23–27",IF(C5<33,"28–32","33+"))) -> 23–27 | BJ5: =AN5/100 -> 0.536 | BK5: =AO5/100 -> 0.587 | BL5: =J5/(MAX($J$2:$J$570)) -> 0.61858781 | BM5: =IF(AND(G5>=30,J5>=500),"Conserver","Écarter") -> Conserver | BN5: =AT5/(MAX($AT$2:$AT$570)) -> 0.86245473 | BO5: =G5*D5 -> 1770 | BP5: =IF(BO5>0,U5/BO5,"") -> 0.21751412 | BQ5: =IF(V5>0,U5/V5,0) -> 2.1388889 | BR5: =IF(G5>0,AV5/G5,"") -> 0.23163842
A6: Anthony Edwards | B6: MIN | C6: 23 | D6: 79 | E6: 48 | F6: 31 | G6: 36.3 | H6: 2180 | I6: 719 | J6: 1612 | K6: 44.7 | L6: 324 | M6: 814 | N6: 39.5 | O6: 419 | P6: 498 | Q6: 83.7 | R6: 63 | S6: 387 | T6: 450 | U6: 356 | V6: 253 | W6: 95 | X6: 47 | Y6: 150 | Z6: 3429 | AA6: 7 | AB6: 0 | AC6: 3.7 | AD6: 116.2 | AE6: 111.4 | AF6: 4.8 | AG6: 20.9 | AH6: 1.44 | AI6: 14.8 | AJ6: 2.1 | AK6: 13.1 | AL6: 7.7 | AM6: 10.3 | AN6: 54.7 | AO6: 59.5 | AP6: 30.7 | AQ6: 98.27 | AR6: 14 | AS6: 5883 | AT6: =H6/D6 -> 27.594937 | AU6: =U6/D6 -> 4.5063291 | AV6: =T6/D6 -> 5.6962025 | AW6: =R6/D6 -> 0.79746835 | AX6: =S6/D6 -> 4.8987342 | AY6: =W6/D6 -> 1.2025316 | AZ6: =X6/D6 -> 0.59493671 | BA6: =V6/D6 -> 3.2025316 | BB6: =IF(G6>0,AT6/G6,"") -> 0.76019109 | BC6: =IF(BA6>0,AU6/BA6,"") -> 1.4071146 | BD6: =IF(G6>0,AY6/G6,"") -> 0.033127594 | BE6: =IF(G6>0,AZ6/G6,"") -> 0.016389441 | BF6: =IF(G6>0,AW6/G6,"") -> 0.021968825 | BG6: =IF(G6>0,AX6/G6,"") -> 0.13495135 | BH6: =IF(G6<10,"<10 min",IF(G6<20,"10–19 min",IF(G6<30,"20–29 min",IF(G6<40,"30–39 min","40+ min")))) -> 30–39 min | BI6: =IF(C6<23,"18–22",IF(C6<28,"23–27",IF(C6<33,"28–32","33+"))) -> 23–27 | BJ6: =AN6/100 -> 0.547 | BK6: =AO6/100 -> 0.595 | BL6: =J6/(MAX($J$2:$J$570)) -> 0.97284249 | BM6: =IF(AND(G6>=30,J6>=500),"Conserver","Écarter") -> Conserver | BN6: =AT6/(MAX($AT$2:$AT$570)) -> 0.84394977 | BO6: =G6*D6 -> 2867.7 | BP6: =IF(BO6>0,U6/BO6,"") -> 0.1241413 | BQ6: =IF(V6>0,U6/V6,0) -> 1.4071146 | BR6: =IF(G6>0,AV6/G6,"") -> 0.15692018
A7: Jayson Tatum | B7: BOS | C7: 27 | D7: 72 | E7: 53 | F7: 19 | G7: 36.4 | H7: 1930 | I7: 662 | J7: 1462 | K7: 45.2 | L7: 252 | M7: 727 | N7: 34.3 | O7: 360 | P7: 439 | Q7: 81.4 | R7: 50 | S7: 576 | T7: 626 | U7: 432 | V7: 209 | W7: 79 | X7: 36 | Y7: 158 | Z7: 3456 | AA7: 31 | AB7: 2 | AC7: 7.4 | AD7: 119.6 | AE7: 109.8 | AF7: 9.8 | AG7: 26.6 | AH7: 2.6 | AI7: 18.9 | AJ7: 1.7 | AK7: 20.6 | AL7: 11.2 | AM7: 9.2 | AN7: 53.7 | AO7: 58.2 | AP7: 30.1 | AQ7: 98.14 | AR7: 15.8 | AS7: 5368 | AT7: =H7/D7 -> 26.805556 | AU7: =U7/D7 -> 6 | AV7: =T7/D7 -> 8.6944444 | AW7: =R7/D7 -> 0.69444444 | AX7: =S7/D7 -> 8 | AY7: =W7/D7 -> 1.0972222 | AZ7: =X7/D7 -> 0.5 | BA7: =V7/D7 -> 2.9027778 | BB7: =IF(G7>0,AT7/G7,"") -> 0.73641636 | BC7: =IF(BA7>0,AU7/BA7,"") -> 2.0669856 | BD7: =IF(G7>0,AY7/G7,"") -> 0.030143468 | BE7: =IF(G7>0,AZ7/G7,"") -> 0.013736264 | BF7: =IF(G7>0,AW7/G7,"") -> 0.019078144 | BG7: =IF(G7>0,AX7/G7,"") -> 0.21978022 | BH7: =IF(G7<10,"<10 min",IF(G7<20,"10–19 min",IF(G7<30,"20–29 min",IF(G7<40,"30–39 min","40+ min")))) -> 30–39 min | BI7: =IF(C7<23,"18–22",IF(C7<28,"23–27",IF(C7<33,"28–32","33+"))) -> 23–27 | BJ7: =AN7/100 -> 0.537 | BK7: =AO7/100 -> 0.582 | BL7: =J7/(MAX($J$2:$J$570)) -> 0.88231744 | BM7: =IF(AND(G7>=30,J7>=500),"Conserver","Écarter") -> Conserver | BN7: =AT7/(MAX($AT$2:$AT$570)) -> 0.81980774 | BO7: =G7*D7 -> 2620.8 | BP7: =IF(BO7>0,U7/BO7,"") -> 0.16483516 | BQ7: =IF(V7>0,U7/V7,0) -> 2.0669856 | BR7: =IF(G7>0,AV7/G7,"") -> 0.23885836
A8: Kevin Durant | B8: PHX | C8: 36 | D8: 62 | E8: 33 | F8: 29 | G8: 36.5 | H8: 1649 | I8: 589 | J8: 1122 | K8: 52.7 | L8: 161 | M8: 372 | N8: 43 | O8: 304 | P8: 360 | Q8: 83.9 | R8: 25 | S8: 353 | T8: 372 | U8: 260 | V8: 192 | W8: 50 | X8: 74 | Y8: 105 | Z8: 2678 | AA8: 5 | AB8: 0 | AC8: -0.6 | AD8: 116.5 | AE8: 117.4 | AF8: -1 | AG8: 18.8 | AH8: 1.38 | AI8: 15.2 | AJ8: 1.1 | AK8: 14.7 | AL8: 8.4 | AM8: 11 | AN8: 59.8 | AO8: 64.2 | AP8: 28.3 | AQ8: 99.49 | AR8: 14.2 | AS8: 4697 | AT8: =H8/D8 -> 26.596774 | AU8: =U8/D8 -> 4.1935484 | AV8: =T8/D8 -> 6 | AW8: =R8/D8 -> 0.40322581 | AX8: =S8/D8 -> 5.6935484 | AY8: =W8/D8 -> 0.80645161 | AZ8: =X8/D8 -> 1.1935484 | BA8: =V8/D8 -> 3.0967742 | BB8: =IF(G8>0,AT8/G8,"") -> 0.72867875 | BC8: =IF(BA8>0,AU8/BA8,"") -> 1.3541667 | BD8: =IF(G8>0,AY8/G8,"") -> 0.022094565 | BE8: =IF(G8>0,AZ8/G8,"") -> 0.032699956 | BF8: =IF(G8>0,AW8/G8,"") -> 0.011047282 | BG8: =IF(G8>0,AX8/G8,"") -> 0.15598763 | BH8: =IF(G8<10,"<10 min",IF(G8<20,"10–19 min",IF(G8<30,"20–29 min",IF(G8<40,"30–39 min","40+ min")))) -> 30–39 min | BI8: =IF(C8<23,"18–22",IF(C8<28,"23–27",IF(C8<33,"28–32","33+"))) -> 33+ | BJ8: =AN8/100 -> 0.598 | BK8: =AO8/100 -> 0.642 | BL8: =J8/(MAX($J$2:$J$570)) -> 0.67712734 | BM8: =IF(AND(G8>=30,J8>=500),"Conserver","Écarter") -> Conserver | BN8: =AT8/(MAX($AT$2:$AT$570)) -> 0.81342247 | BO8: =G8*D8 -> 2263 | BP8: =IF(BO8>0,U8/BO8,"") -> 0.11489174 | BQ8: =IF(V8>0,U8/V8,0) -> 1.3541667 | BR8: =IF(G8>0,AV8/G8,"") -> 0.16438356
A9: Tyrese Maxey | B9: PHI | C9: 24 | D9: 52 | E9: 20 | F9: 32 | G9: 37.7 | H9: 1368 | I9: 478 | J9: 1092 | K9: 43.7 | L9: 161 | M9: 478 | N9: 33.7 | O9: 255 | P9: 291 | Q9: 87.9 | R9: 16 | S9: 161 | T9: 172 | U9: 317 | V9: 125 | W9: 94 | X9: 21 | Y9: 114 | Z9: 2267 | AA9: 8 | AB9: 1 | AC9: -2.4 | AD9: 113.8 | AE9: 117.4 | AF9: -3.5 | AG9: 27.6 | AH9: 2.56 | AI9: 19.2 | AJ9: 0.7 | AK9: 8.7 | AL9: 4.5 | AM9: 7.5 | AN9: 51.1 | AO9: 56.2 | AP9: 29.3 | AQ9: 98.34 | AR9: 12.7 | AS9: 4024 | AT9: =H9/D9 -> 26.307692 | AU9: =U9/D9 -> 6.0961538 | AV9: =T9/D9 -> 3.3076923 | AW9: =R9/D9 -> 0.30769231 | AX9: =S9/D9 -> 3.0961538 | AY9: =W9/D9 -> 1.8076923 | AZ9: =X9/D9 -> 0.40384615 | BA9: =V9/D9 -> 2.4038462 | BB9: =IF(G9>0,AT9/G9,"") -> 0.69781677 | BC9: =IF(BA9>0,AU9/BA9,"") -> 2.536 | BD9: =IF(G9>0,AY9/G9,"") -> 0.047949398 | BE9: =IF(G9>0,AZ9/G9,"") -> 0.0107121 | BF9: =IF(G9>0,AW9/G9,"") -> 0.0081615997 | BG9: =IF(G9>0,AX9/G9,"") -> 0.082126097 | BH9: =IF(G9<10,"<10 min",IF(G9<20,"10–19 min",IF(G9<30,"20–29 min",IF(G9<40,"30–39 min","40+ min")))) -> 30–39 min | BI9: =IF(C9<23,"18–22",IF(C9<28,"23–27",IF(C9<33,"28–32","33+"))) -> 23–27 | BJ9: =AN9/100 -> 0.511 | BK9: =AO9/100 -> 0.562 | BL9: =J9/(MAX($J$2:$J$570)) -> 0.65902233 | BM9: =IF(AND(G9>=30,J9>=500),"Conserver","Écarter") -> Conserver | BN9: =AT9/(MAX($AT$2:$AT$570)) -> 0.80458133 | BO9: =G9*D9 -> 1960.4 | BP9: =IF(BO9>0,U9/BO9,"") -> 0.16170169 | BQ9: =IF(V9>0,U9/V9,0) -> 2.536 | BR9: =IF(G9>0,AV9/G9,"") -> 0.087737196
A10: Cade Cunningham | B10: DET | C10: 23 | D10: 70 | E10: 38 | F10: 32 | G10: 35 | H10: 1827 | I10: 686 | J10: 1456 | K10: 46.9 | L10: 147 | M10: 420 | N10: 35.6 | O10: 315 | P10: 371 | Q10: 84.6 | R10: 56 | S10: 371 | T10: 427 | U10: 637 | V10: 308 | W10: 70 | X10: 56 | Y10: 196 | Z10: 3360 | AA10: 31 | AB10: 9 | AC10: 2.5 | AD10: 115 | AE10: 112.2 | AF10: 2.8 | AG10: 40.9 | AH10: 2.06 | AI10: 25 | AJ10: 2.3 | AK10: 14.7 | AL10: 8.6 | AM10: 12.1 | AN10: 52.1 | AO10: 56.5 | AP10: 32.3 | AQ10: 101.57 | AR10: 15.2 | AS10: 5201 | AT10: =H10/D10 -> 26.1 | AU10: =U10/D10 -> 9.1 | AV10: =T10/D10 -> 6.1 | AW10: =R10/D10 -> 0.8 | AX10: =S10/D10 -> 5.3 | AY10: =W10/D10 -> 1 | AZ10: =X10/D10 -> 0.8 | BA10: =V10/D10 -> 4.4 | BB10: =IF(G10>0,AT10/G10,"") -> 0.74571429 | BC10: =IF(BA10>0,AU10/BA10,"") -> 2.0681818 | BD10: =IF(G10>0,AY10/G10,"") -> 0.028571429 | BE10: =IF(G10>0,AZ10/G10,"") -> 0.022857143 | BF10: =IF(G10>0,AW10/G10,"") -> 0.022857143 | BG10: =IF(G10>0,AX10/G10,"") -> 0.15142857 | BH10: =IF(G10<10,"<10 min",IF(G10<20,"10–19 min",IF(G10<30,"20–29 min",IF(G10<40,"30–39 min","40+ min")))) -> 30–39 min | BI10: =IF(C10<23,"18–22",IF(C10<28,"23–27",IF(C10<33,"28–32","33+"))) -> 23–27 | BJ10: =AN10/100 -> 0.521 | BK10: =AO10/100 -> 0.565 | BL10: =J10/(MAX($J$2:$J$570)) -> 0.87869644 | BM10: =IF(AND(G10>=30,J10>=500),"Conserver","Écarter") -> Conserver | BN10: =AT10/(MAX($AT$2:$AT$570)) -> 0.79822938 | BO10: =G10*D10 -> 2450 | BP10: =IF(BO10>0,U10/BO10,"") -> 0.26 | BQ10: =IF(V10>0,U10/V10,0) -> 2.0681818 | BR10: =IF(G10>0,AV10/G10,"") -> 0.17428571
A11: Jalen Brunson | B11: NYK | C11: 28 | D11: 65 | E11: 40 | F11: 25 | G11: 35.4 | H11: 1690 | I11: 585 | J11: 1203 | K11: 48.8 | L11: 150 | M11: 397 | N11: 38.3 | O11: 371 | P11: 449 | Q11: 82.1 | R11: 26 | S11: 163 | T11: 189 | U11: 475 | V11: 163 | W11: 59 | X11: 7 | Y11: 137 | Z11: 2665 | AA11: 14 | AB11: 0 | AC11: 2.2 | AD11: 118.3 | AE11: 115.7 | AF11: 2.6 | AG11: 31.8 | AH11: 2.9 | AI11: 23.5 | AJ11: 1.2 | AK11: 7.2 | AL11: 4.2 | AM11: 8.1 | AN11: 55.1 | AO11: 60.5 | AP11: 28.9 | AQ11: 97.79 | AR11: 13.8 | AS11: 4697 | AT11: =H11/D11 -> 26 | AU11: =U11/D11 -> 7.3076923 | AV11: =T11/D11 -> 2.9076923 | AW11: =R11/D11 -> 0.4 | AX11: =S11/D11 -> 2.5076923 | AY11: =W11/D11 -> 0.90769231 | AZ11: =X11/D11 -> 0.10769231 | BA11: =V11/D11 -> 2.5076923 | BB11: =IF(G11>0,AT11/G11,"") -> 0.73446328 | BC11: =IF(BA11>0,AU11/BA11,"") -> 2.9141104 | BD11: =IF(G11>0,AY11/G11,"") -> 0.025641026 | BE11: =IF(G11>0,AZ11/G11,"") -> 0.0030421556 | BF11: =IF(G11>0,AW11/G11,"") -> 0.011299435 | BG11: =IF(G11>0,AX11/G11,"") -> 0.070838766 | BH11: =IF(G11<10,"<10 min",IF(G11<20,"10–19 min",IF(G11<30,"20–29 min",IF(G11<40,"30–39 min","40+ min")))) -> 30–39 min | BI11: =IF(C11<23,"18–22",IF(C11<28,"23–27",IF(C11<33,"28–32","33+"))) -> 28–32 | BJ11: =AN11/100 -> 0.551 | BK11: =AO11/100 -> 0.605 | BL11: =J11/(MAX($J$2:$J$570)) -> 0.72601086 | BM11: =IF(AND(G11>=30,J11>=500),"Conserver","Écarter") -> Conserver | BN11: =AT11/(MAX($AT$2:$AT$570)) -> 0.79517103 | BO11: =G11*D11 -> 2301 | BP11: =IF(BO11>0,U11/BO11,"") -> 0.20643199 | BQ11: =IF(V11>0,U11/V11,0) -> 2.9141104 | BR11: =IF(G11>0,AV11/G11,"") -> 0.082138201
A12: Paolo Banchero | B12: ORL | C12: 22 | D12: 46 | E12: 21 | F12: 25 | G12: 34.4 | H12: 1191 | I12: 414 | J12: 911 | K12: 45.2 | L12: 87 | M12: 271 | N12: 32 | O12: 281 | P12: 386 | Q12: 72.7 | R12: 51 | S12: 294 | T12: 345 | U12: 221 | V12: 138 | W12: 37 | X12: 28 | Y12: 97 | Z12: 1992 | AA12: 11 | AB12: 0 | AC12: -0.5 | AD12: 109.1 | AE12: 109.6 | AF12: -0.6 | AG12: 26.2 | AH12: 1.61 | AI12: 15.3 | AJ12: 3.1 | AK12: 19.2 | AL12: 10.8 | AM12: 9.5 | AN12: 50 | AO12: 55.1 | AP12: 33 | AQ12: 97.29 | AR12: 15.7 | AS12: 3204 | AT12: =H12/D12 -> 25.891304 | AU12: =U12/D12 -> 4.8043478 | AV12: =T12/D12 -> 7.5 | AW12: =R12/D12 -> 1.1086957 | AX12: =S12/D12 -> 6.3913043 | AY12: =W12/D12 -> 0.80434783 | AZ12: =X12/D12 -> 0.60869565 | BA12: =V12/D12 -> 3 | BB12: =IF(G12>0,AT12/G12,"") -> 0.7526542 | BC12: =IF(BA12>0,AU12/BA12,"") -> 1.6014493 | BD12: =IF(G12>0,AY12/G12,"") -> 0.023382204 | BE12: =IF(G12>0,AZ12/G12,"") -> 0.017694641 | BF12: =IF(G12>0,AW12/G12,"") -> 0.032229525 | BG12: =IF(G12>0,AX12/G12,"") -> 0.18579373 | BH12: =IF(G12<10,"<10 min",IF(G12<20,"10–19 min",IF(G12<30,"20–29 min",IF(G12<40,"30–39 min","40+ min")))) -> 30–39 min | BI12: =IF(C12<23,"18–22",IF(C12<28,"23–27",IF(C12<33,"28–32","33+"))) -> 18–22 | BJ12: =AN12/100 -> 0.5 | BK12: =AO12/100 -> 0.551 | BL12: =J12/(MAX($J$2:$J$570)) -> 0.54978877 | BM12: =IF(AND(G12>=30,J12>=500),"Conserver","Écarter") -> Conserver | BN12: =AT12/(MAX($AT$2:$AT$570)) -> 0.79184673 | BO12: =G12*D12 -> 1582.4 | BP12: =IF(BO12>0,U12/BO12,"") -> 0.13966127 | BQ12: =IF(V12>0,U12/V12,0) -> 1.6014493 | BR12: =IF(G12>0,AV12/G12,"") -> 0.21802326
A13: Devin Booker | B13: PHX | C13: 28 | D13: 75 | E13: 35 | F13: 40 | G13: 37.3 | H13: 1920 | I13: 653 | J13: 1418 | K13: 46.1 | L13: 180 | M13: 548 | N13: 33.2 | O13: 435 | P13: 480 | Q13: 89.4 | R13: 75 | S13: 233 | T13: 308 | U13: 533 | V13: 218 | W13: 68 | X13: 15 | Y13: 195 | Z13: 3113 | AA13: 16 | AB13: 0 | AC13: -2.4 | AD13: 115.3 | AE13: 118.5 | AF13: -3.2 | AG13: 30.1 | AH13: 2.4 | AI13: 22.4 | AJ13: 2.8 | AK13: 8 | AL13: 5.5 | AM13: 9.3 | AN13: 52.5 | AO13: 58.9 | AP13: 28.5 | AQ13: 98.72 | AR13: 12.2 | AS13: 5752 | AT13: =H13/D13 -> 25.6 | AU13: =U13/D13 -> 7.1066667 | AV13: =T13/D13 -> 4.1066667 | AW13: =R13/D13 -> 1 | AX13: =S13/D13 -> 3.1066667 | AY13: =W13/D13 -> 0.90666667 | AZ13: =X13/D13 -> 0.2 | BA13: =V13/D13 -> 2.9066667 | BB13: =IF(G13>0,AT13/G13,"") -> 0.68632708 | BC13: =IF(BA13>0,AU13/BA13,"") -> 2.4449541 | BD13: =IF(G13>0,AY13/G13,"") -> 0.024307417 | BE13: =IF(G13>0,AZ13/G13,"") -> 0.0053619303 | BF13: =IF(G13>0,AW13/G13,"") -> 0.026809651 | BG13: =IF(G13>0,AX13/G13,"") -> 0.083288651 | BH13: =IF(G13<10,"<10 min",IF(G13<20,"10–19 min",IF(G13<30,"20–29 min",IF(G13<40,"30–39 min","40+ min")))) -> 30–39 min | BI13: =IF(C13<23,"18–22",IF(C13<28,"23–27",IF(C13<33,"28–32","33+"))) -> 28–32 | BJ13: =AN13/100 -> 0.525 | BK13: =AO13/100 -> 0.589 | BL13: =J13/(MAX($J$2:$J$570)) -> 0.85576343 | BM13: =IF(AND(G13>=30,J13>=500),"Conserver","Écarter") -> Conserver | BN13: =AT13/(MAX($AT$2:$AT$570)) -> 0.78293763 | BO13: =G13*D13 -> 2797.5 | BP13: =IF(BO13>0,U13/BO13,"") -> 0.19052726 | BQ13: =IF(V13>0,U13/V13,0) -> 2.4449541 | BR13: =IF(G13>0,AV13/G13,"") -> 0.1100983
... A570: Jalen McDaniels | B570: WAS | C570: 27 | D570: 4 | E570: 2 | F570: 2 | G570: 1.8 | H570: 0 | I570: 0 | J570: 0 | K570: 0 | L570: 0 | M570: 0 | N570: 0 | O570: 0 | P570: 0 | Q570: 0 | R570: 0 | S570: 0 | T570: 0 | U570: 1 | V570: 0 | W570: 1 | X570: 0 | Y570: 0 | Z570: 4 | AA570: 0 | AB570: 0 | AC570: -0.3 | AD570: 81.3 | AE570: 77.8 | AF570: 3.5 | AG570: 25 | AH570: 0 | AI570: 100 | AJ570: 0 | AK570: 0 | AL570: 0 | AM570: 0 | AN570: 0 | AO570: 0 | AP570: 0 | AQ570: 111.25 | AR570: 11.4 | AS570: 16 | AT570: =H570/D570 -> 0 | AU570: =U570/D570 -> 0.25 | AV570: =T570/D570 -> 0 | AW570: =R570/D570 -> 0 | AX570: =S570/D570 -> 0 | AY570: =W570/D570 -> 0.25 | AZ570: =X570/D570 -> 0 | BA570: =V570/D570 -> 0 | BB570: =IF(G570>0,AT570/G570,"") -> 0 | BC570: =IF(BA570>0,AU570/BA570,"") | BD570: =IF(G570>0,AY570/G570,"") -> 0.13888889 | BE570: =IF(G570>0,AZ570/G570,"") -> 0 | BF570: =IF(G570>0,AW570/G570,"") -> 0 | BG570: =IF(G570>0,AX570/G570,"") -> 0 | BH570: =IF(G570<10,"<10 min",IF(G570<20,"10–19 min",IF(G570<30,"20–29 min",IF(G570<40,"30–39 min","40+ min")))) -> <10 min | BI570: =IF(C570<23,"18–22",IF(C570<28,"23–27",IF(C570<33,"28–32","33+"))) -> 23–27 | BJ570: =AN570/100 -> 0 | BK570: =AO570/100 -> 0 | BL570: =J570/(MAX($J$2:$J$570)) -> 0 | BM570: =IF(AND(G570>=30,J570>=500),"Conserver","Écarter") -> Écarter | BN570: =AT570/(MAX($AT$2:$AT$570)) -> 0 | BO570: =G570*D570 -> 7.2 | BP570: =IF(BO570>0,U570/BO570,"") -> 0.13888889 | BQ570: =IF(V570>0,U570/V570,0) -> 0 | BR570: =IF(G570>0,AV570/G570,"") -> 0

Sheet Filtres_Zones_Critères
BT1: Zones de critères
A2: Sélections selon filtres élaborés divers
BT3: Tot_Min >1000 | BX3: Top Players PTS_pg
BT5: Min_tot | BX5: Players | BZ5: PTS_pg
BT6: >1000 | BX6: Shai Gilgeous-Alexander | BZ6: 32.697368
BX7: Giannis Antetokounmpo | BZ7: 30.402985
A8: Tableau de données complet | BX8: Nikola Jokić | BZ8: 29.6
BX9: Luka Dončić | BZ9: 28.2
A10: Player | B10: Team | C10: Age | D10: GP | E10: W | F10: L | G10: Min | H10: PTS | I10: FGM | J10: FGA | K10: FG% | L10: 15:00 | M10: 3PA | N10: 3P% | O10: FTM | P10: FTA | Q10: FT% | R10: OREB | S10: DREB | T10: REB | U10: AST | V10: TOV | W10: STL | X10: BLK | Y10: PF | Z10: FP | AA10: DD2 | AB10: TD3 | AC10: +/- | AD10: OFFRTG | AE10: DEFRTG | AF10: NETRTG | AG10: AST% | AH10: AST/TO | AI10: AST RATIO | AJ10: OREB% | AK10: DREB% | AL10: REB% | AM10: TO RATIO | AN10: EFG% | AO10: TS% | AP10: USG% | AQ10: PACE | AR10: PIE | AS10: POSS | AT10: PTS_pg | AU10: AST_pg | AV10: REB_pg | AW10: OREB_pg | AX10: DREB_pg | AY10: STL_pg | AZ10: BLK_pg | BA10: TOV_pg | BB10: PTS_pg/Min | BC10: AST_pg/TOV_pg | BD10: STL_pg/Min | BE10: BLK_pg/Min | BF10: OREB_pg/Min | BG10: DREB_pg/Min | BH10: Classe_Min | BI10: Classe_Age | BJ10: EFG%_corr | BK10: TS%_corr | BL10: FGA_norm | BM10: Filtre joueur | BN10: PTG_pg_Norm | BO10: Min_tot | BP10: AST/Min | BQ10: AST/TOV | BR10: REB_pg/Min | BS10: Def Impact Score | BT10: Moy. Gén. Réussite Tirs | BU10: Moy. Gén. Réussite 3 Points | BV10: Moy. Gén. Réussite Lancers Francs | BX10: Anthony Edwards | BZ10: 27.594937
A11: Shai Gilgeous-Alexander | B11: OKC | C11: 26 | D11: 76 | E11: 63 | F11: 13 | G11: 34.2 | H11: 2485 | I11: 859 | J11: 1657 | K11: 51.9 | L11: 160 | M11: 433 | N11: 37.5 | O11: 600 | P11: 669 | Q11: 89.8 | R11: 68 | S11: 312 | T11: 380 | U11: 486 | V11: 182 | W11: 129 | X11: 76 | Y11: 167 | Z11: 4112 | AA11: 6 | AB11: 0 | AC11: 12.1 | AD11: 122.4 | AE11: 105.7 | AF11: 16.7 | AG11: 29.9 | AH11: 2.66 | AI11: 18.7 | AJ11: 2.5 | AK11: 11.2 | AL11: 6.9 | AM11: 7 | AN11: 56.9 | AO11: 63.7 | AP11: 33.6 | AQ11: 101.91 | AR11: 19.9 | AS11: 5514 | AT11: =H11/D11 -> 32.697368 | AU11: =U11/D11 -> 6.3947368 | AV11: =T11/D11 -> 5 | AW11: =R11/D11 -> 0.89473684 | AX11: =S11/D11 -> 4.1052632 | AY11: =W11/D11 -> 1.6973684 | AZ11: =X11/D11 -> 1 | BA11: =V11/D11 -> 2.3947368 | BB11: =IF(G11>0,AT11/G11,"") -> 0.9560634 | BC11: =IF(BA11>0,AU11/BA11,"") -> 2.6703297 | BD11: =IF(G11>0,AY11/G11,"") -> 0.049630656 | BE11: =IF(G11>0,AZ11/G11,"") -> 0.029239766 | BF11: =IF(G11>0,AW11/G11,"") -> 0.026161896 | BG11: =IF(G11>0,AX11/G11,"") -> 0.12003693 | BH11: =IF(G11<10,"<10 min",IF(G11<20,"10–19 min",IF(G11<30,"20–29 min",IF(G11<40,"30–39 min","40+ min")))) -> 30–39 min | BI11: =IF(C11<23,"18–22",IF(C11<28,"23–27",IF(C11<33,"28–32","33+"))) -> 23–27 | BJ11: =AN11/100 -> 0.569 | BK11: =AO11/100 -> 0.637 | BL11: =J11/(MAX($J$11:$J$579)) -> 1 | BM11: =IF(AND(G11>=30,J11>=500),"Conserver","Écarter") -> Conserver | BN11: =AT11/(MAX($AT$11:$AT$579)) -> 1 | BO11: =G11*D11 -> 2599.2 | BP11: =IF(BO11>0,U11/BO11,"") -> 0.18698061 | BQ11: =IF(V11>0,U11/V11,0) -> 2.6703297 | BR11: =IF(G11>0,AV11/G11,"") -> 0.14619883 | BS11: =AVERAGE(Tableau1[[#This Row],[STL_pg/Min]],Tableau1[[#This Row],[BLK_pg/Min]],Tableau1[[#This Row],[REB_pg/Min]]) -> 0.075023084 | BT11: =AVERAGE(Tableau1[FG%]) -> 44.610896 | BU11: =AVERAGE(Tableau1[3P%]) -> 29.90246 | BV11: =AVERAGE(Tableau1[FT%]) -> 72.024077 | BX11: Jayson Tatum | BZ11: 26.805556
A12: Giannis Antetokounmpo | B12: MIL | C12: 30 | D12: 67 | E12: 40 | F12: 27 | G12: 34.2 | H12: 2037 | I12: 791 | J12: 1320 | K12: 60.1 | L12: 13 | M12: 60 | N12: 22.2 | O12: 436 | P12: 710 | Q12: 61.7 | R12: 147 | S12: 650 | T12: 797 | U12: 436 | V12: 208 | W12: 60 | X12: 80 | Y12: 154 | Z12: 3846 | AA12: 55 | AB12: 11 | AC12: 5 | AD12: 118.9 | AE12: 111.7 | AF12: 7.2 | AG12: 33.9 | AH12: 2.1 | AI12: 19.2 | AJ12: 6.7 | AK12: 26.6 | AL12: 17.2 | AM12: 9.1 | AN12: 60.7 | AO12: 62.5 | AP12: 34.6 | AQ12: 100.18 | AR12: 21 | AS12: 4772 | AT12: =H12/D12 -> 30.402985 | AU12: =U12/D12 -> 6.5074627 | AV12: =T12/D12 -> 11.895522 | AW12: =R12/D12 -> 2.1940299 | AX12: =S12/D12 -> 9.7014925 | AY12: =W12/D12 -> 0.89552239 | AZ12: =X12/D12 -> 1.1940299 | BA12: =V12/D12 -> 3.1044776 | BB12: =IF(G12>0,AT12/G12,"") -> 0.88897617 | BC12: =IF(BA12>0,AU12/BA12,"") -> 2.0961538 | BD12: =IF(G12>0,AY12/G12,"") -> 0.026184865 | BE12: =IF(G12>0,AZ12/G12,"") -> 0.034913154 | BF12: =IF(G12>0,AW12/G12,"") -> 0.06415292 | BG12: =IF(G12>0,AX12/G12,"") -> 0.28366937 | BH12: =IF(G12<10,"<10 min",IF(G12<20,"10–19 min",IF(G12<30,"20–29 min",IF(G12<40,"30–39 min","40+ min")))) -> 30–39 min | BI12: =IF(C12<23,"18–22",IF(C12<28,"23–27",IF(C12<33,"28–32","33+"))) -> 28–32 | BJ12: =AN12/100 -> 0.607 | BK12: =AO12/100 -> 0.625 | BL12: =J12/(MAX($J$11:$J$579)) -> 0.7966204 | BM12: =IF(AND(G12>=30,J12>=500),"Conserver","Écarter") -> Conserver | BN12: =AT12/(MAX($AT$11:$AT$579)) -> 0.92982972 | BO12: =G12*D12 -> 2291.4 | BP12: =IF(BO12>0,U12/BO12,"") -> 0.19027669 | BQ12: =IF(V12>0,U12/V12,0) -> 2.0961538 | BR12: =IF(G12>0,AV12/G12,"") -> 0.34782229 | BS12: =AVERAGE(Tableau1[[#This Row],[STL_pg/Min]],Tableau1[[#This Row],[BLK_pg/Min]],Tableau1[[#This Row],[REB_pg/Min]]) -> 0.13630677 | BT12: =AVERAGE(Tableau1[FG%]) -> 44.610896 | BU12: =AVERAGE(Tableau1[3P%]) -> 29.90246 | BV12: =AVERAGE(Tableau1[FT%]) -> 72.024077 | BX12: Kevin Durant | BZ12: 26.596774
A13: Nikola Jokić | B13: DEN | C13: 30 | D13: 70 | E13: 46 | F13: 24 | G13: 36.7 | H13: 2072 | I13: 784 | J13: 1365 | K13: 57.6 | L13: 140 | M13: 329 | N13: 41.7 | O13: 364 | P13: 448 | Q13: 80 | R13: 203 | S13: 693 | T13: 889 | U13: 714 | V13: 231 | W13: 126 | X13: 42 | Y13: 161 | Z13: 4501 | AA13: 59 | AB13: 34 | AC13: 8.5 | AD13: 125.6 | AE13: 115.1 | AF13: 10.5 | AG13: 39.8 | AH13: 3.11 | AI13: 28.7 | AJ13: 8.3 | AK13: 25.2 | AL13: 17.3 | AM13: 9.2 | AN13: 62.7 | AO13: 66.3 | AP13: 28.5 | AQ13: 101.99 | AR13: 20.6 | AS13: 5471 | AT13: =H13/D13 -> 29.6 | AU13: =U13/D13 -> 10.2 | AV13: =T13/D13 -> 12.7 | AW13: =R13/D13 -> 2.9 | AX13: =S13/D13 -> 9.9 | AY13: =W13/D13 -> 1.8 | AZ13: =X13/D13 -> 0.6 | BA13: =V13/D13 -> 3.3 | BB13: =IF(G13>0,AT13/G13,"") -> 0.80653951 | BC13: =IF(BA13>0,AU13/BA13,"") -> 3.0909091 | BD13: =IF(G13>0,AY13/G13,"") -> 0.049046322 | BE13: =IF(G13>0,AZ13/G13,"") -> 0.016348774 | BF13: =IF(G13>0,AW13/G13,"") -> 0.079019074 | BG13: =IF(G13>0,AX13/G13,"") -> 0.26975477 | BH13: =IF(G13<10,"<10 min",IF(G13<20,"10–19 min",IF(G13<30,"20–29 min",IF(G13<40,"30–39 min","40+ min")))) -> 30–39 min | BI13: =IF(C13<23,"18–22",IF(C13<28,"23–27",IF(C13<33,"28–32","33+"))) -> 28–32 | BJ13: =AN13/100 -> 0.627 | BK13: =AO13/100 -> 0.663 | BL13: =J13/(MAX($J$11:$J$579)) -> 0.82377791 | BM13: =IF(AND(G13>=30,J13>=500),"Conserver","Écarter") -> Conserver | BN13: =AT13/(MAX($AT$11:$AT$579)) -> 0.90527163 | BO13: =G13*D13 -> 2569 | BP13: =IF(BO13>0,U13/BO13,"") -> 0.27792916 | BQ13: =IF(V13>0,U13/V13,0) -> 3.0909091 | BR13: =IF(G13>0,AV13/G13,"") -> 0.34604905 | BS13: =AVERAGE(Tableau1[[#This Row],[STL_pg/Min]],Tableau1[[#This Row],[BLK_pg/Min]],Tableau1[[#This Row],[REB_pg/Min]]) -> 0.13714805 | BT13: =AVERAGE(Tableau1[FG%]) -> 44.610896 | BU13: =AVERAGE(Tableau1[3P%]) -> 29.90246 | BV13: =AVERAGE(Tableau1[FT%]) -> 72.024077 | BX13: Tyrese Maxey | BZ13: 26.307692
A14: Luka Dončić | B14: LAL | C14: 26 | D14: 50 | E14: 31 | F14: 19 | G14: 35.4 | H14: 1410 | I14: 460 | J14: 1025 | K14: 45 | L14: 175 | M14: 480 | N14: 36.8 | O14: 310 | P14: 395 | Q14: 78.2 | R14: 40 | S14: 370 | T14: 410 | U14: 385 | V14: 180 | W14: 90 | X14: 20 | Y14: 125 | Z14: 2625 | AA14: 21 | AB14: 5 | AC14: 6.9 | AD14: 119.6 | AE14: 110.5 | AF14: 9.1 | AG14: 34.2 | AH14: 2.14 | AI14: 21.8 | AJ14: 2.3 | AK14: 19.8 | AL14: 11.2 | AM14: 10.2 | AN14: 53.6 | AO14: 58.7 | AP14: 32.8 | AQ14: 100.22 | AR14: 17 | AS14: 3696 | AT14: =H14/D14 -> 28.2 | AU14: =U14/D14 -> 7.7 | AV14: =T14/D14 -> 8.2 | AW14: =R14/D14 -> 0.8 | AX14: =S14/D14 -> 7.4 | AY14: =W14/D14 -> 1.8 | AZ14: =X14/D14 -> 0.4 | BA14: =V14/D14 -> 3.6 | BB14: =IF(G14>0,AT14/G14,"") -> 0.79661017 | BC14: =IF(BA14>0,AU14/BA14,"") -> 2.1388889 | BD14: =IF(G14>0,AY14/G14,"") -> 0.050847458 | BE14: =IF(G14>0,AZ14/G14,"") -> 0.011299435 | BF14: =IF(G14>0,AW14/G14,"") -> 0.02259887 | BG14: =IF(G14>0,AX14/G14,"") -> 0.20903955 | BH14: =IF(G14<10,"<10 min",IF(G14<20,"10–19 min",IF(G14<30,"20–29 min",IF(G14<40,"30–39 min","40+ min")))) -> 30–39 min | BI14: =IF(C14<23,"18–22",IF(C14<28,"23–27",IF(C14<33,"28–32","33+"))) -> 23–27 | BJ14: =AN14/100 -> 0.536 | BK14: =AO14/100 -> 0.587 | BL14: =J14/(MAX($J$11:$J$579)) -> 0.61858781 | BM14: =IF(AND(G14>=30,J14>=500),"Conserver","Écarter") -> Conserver | BN14: =AT14/(MAX($AT$11:$AT$579)) -> 0.86245473 | BO14: =G14*D14 -> 1770 | BP14: =IF(BO14>0,U14/BO14,"") -> 0.21751412 | BQ14: =IF(V14>0,U14/V14,0) -> 2.1388889 | BR14: =IF(G14>0,AV14/G14,"") -> 0.23163842 | BS14: =AVERAGE(Tableau1[[#This Row],[STL_pg/Min]],Tableau1[[#This Row],[BLK_pg/Min]],Tableau1[[#This Row],[REB_pg/Min]]) -> 0.097928437 | BT14: =AVERAGE(Tableau1[FG%]) -> 44.610896 | BU14: =AVERAGE(Tableau1[3P%]) -> 29.90246 | BV14: =AVERAGE(Tableau1[FT%]) -> 72.024077 | BX14: Cade Cunningham | BZ14: 26.1
A15: Anthony Edwards | B15: MIN | C15: 23 | D15: 79 | E15: 48 | F15: 31 | G15: 36.3 | H15: 2180 | I15: 719 | J15: 1612 | K15: 44.7 | L15: 324 | M15: 814 | N15: 39.5 | O15: 419 | P15: 498 | Q15: 83.7 | R15: 63 | S15: 387 | T15: 450 | U15: 356 | V15: 253 | W15: 95 | X15: 47 | Y15: 150 | Z15: 3429 | AA15: 7 | AB15: 0 | AC15: 3.7 | AD15: 116.2 | AE15: 111.4 | AF15: 4.8 | AG15: 20.9 | AH15: 1.44 | AI15: 14.8 | AJ15: 2.1 | AK15: 13.1 | AL15: 7.7 | AM15: 10.3 | AN15: 54.7 | AO15: 59.5 | AP15: 30.7 | AQ15: 98.27 | AR15: 14 | AS15: 5883 | AT15: =H15/D15 -> 27.594937 | AU15: =U15/D15 -> 4.5063291 | AV15: =T15/D15 -> 5.6962025 | AW15: =R15/D15 -> 0.79746835 | AX15: =S15/D15 -> 4.8987342 | AY15: =W15/D15 -> 1.2025316 | AZ15: =X15/D15 -> 0.59493671 | BA15: =V15/D15 -> 3.2025316 | BB15: =IF(G15>0,AT15/G15,"") -> 0.76019109 | BC15: =IF(BA15>0,AU15/BA15,"") -> 1.4071146 | BD15: =IF(G15>0,AY15/G15,"") -> 0.033127594 | BE15: =IF(G15>0,AZ15/G15,"") -> 0.016389441 | BF15: =IF(G15>0,AW15/G15,"") -> 0.021968825 | BG15: =IF(G15>0,AX15/G15,"") -> 0.13495135 | BH15: =IF(G15<10,"<10 min",IF(G15<20,"10–19 min",IF(G15<30,"20–29 min",IF(G15<40,"30–39 min","40+ min")))) -> 30–39 min | BI15: =IF(C15<23,"18–22",IF(C15<28,"23–27",IF(C15<33,"28–32","33+"))) -> 23–27 | BJ15: =AN15/100 -> 0.547 | BK15: =AO15/100 -> 0.595 | BL15: =J15/(MAX($J$11:$J$579)) -> 0.97284249 | BM15: =IF(AND(G15>=30,J15>=500),"Conserver","Écarter") -> Conserver | BN15: =AT15/(MAX($AT$11:$AT$579)) -> 0.84394977 | BO15: =G15*D15 -> 2867.7 | BP15: =IF(BO15>0,U15/BO15,"") -> 0.1241413 | BQ15: =IF(V15>0,U15/V15,0) -> 1.4071146 | BR15: =IF(G15>0,AV15/G15,"") -> 0.15692018 | BS15: =AVERAGE(Tableau1[[#This Row],[STL_pg/Min]],Tableau1[[#This Row],[BLK_pg/Min]],Tableau1[[#This Row],[REB_pg/Min]]) -> 0.068812405 | BT15: =AVERAGE(Tableau1[FG%]) -> 44.610896 | BU15: =AVERAGE(Tableau1[3P%]) -> 29.90246 | BV15: =AVERAGE(Tableau1[FT%]) -> 72.024077 | BX15: Jalen Brunson | BZ15: 26
A16: Jayson Tatum | B16: BOS | C16: 27 | D16: 72 | E16: 53 | F16: 19 | G16: 36.4 | H16: 1930 | I16: 662 | J16: 1462 | K16: 45.2 | L16: 252 | M16: 727 | N16: 34.3 | O16: 360 | P16: 439 | Q16: 81.4 | R16: 50 | S16: 576 | T16: 626 | U16: 432 | V16: 209 | W16: 79 | X16: 36 | Y16: 158 | Z16: 3456 | AA16: 31 | AB16: 2 | AC16: 7.4 | AD16: 119.6 | AE16: 109.8 | AF16: 9.8 | AG16: 26.6 | AH16: 2.6 | AI16: 18.9 | AJ16: 1.7 | AK16: 20.6 | AL16: 11.2 | AM16: 9.2 | AN16: 53.7 | AO16: 58.2 | AP16: 30.1 | AQ16: 98.14 | AR16: 15.8 | AS16: 5368 | AT16: =H16/D16 -> 26.805556 | AU16: =U16/D16 -> 6 | AV16: =T16/D16 -> 8.6944444 | AW16: =R16/D16 -> 0.69444444 | AX16: =S16/D16 -> 8 | AY16: =W16/D16 -> 1.0972222 | AZ16: =X16/D16 -> 0.5 | BA16: =V16/D16 -> 2.9027778 | BB16: =IF(G16>0,AT16/G16,"") -> 0.73641636 | BC16: =IF(BA16>0,AU16/BA16,"") -> 2.0669856 | BD16: =IF(G16>0,AY16/G16,"") -> 0.030143468 | BE16: =IF(G16>0,AZ16/G16,"") -> 0.013736264 | BF16: =IF(G16>0,AW16/G16,"") -> 0.019078144 | BG16: =IF(G16>0,AX16/G16,"") -> 0.21978022 | BH16: =IF(G16<10,"<10 min",IF(G16<20,"10–19 min",IF(G16<30,"20–29 min",IF(G16<40,"30–39 min","40+ min")))) -> 30–39 min | BI16: =IF(C16<23,"18–22",IF(C16<28,"23–27",IF(C16<33,"28–32","33+"))) -> 23–27 | BJ16: =AN16/100 -> 0.537 | BK16: =AO16/100 -> 0.582 | BL16: =J16/(MAX($J$11:$J$579)) -> 0.88231744 | BM16: =IF(AND(G16>=30,J16>=500),"Conserver","Écarter") -> Conserver | BN16: =AT16/(MAX($AT$11:$AT$579)) -> 0.81980774 | BO16: =G16*D16 -> 2620.8 | BP16: =IF(BO16>0,U16/BO16,"") -> 0.16483516 | BQ16: =IF(V16>0,U16/V16,0) -> 2.0669856 | BR16: =IF(G16>0,AV16/G16,"") -> 0.23885836 | BS16: =AVERAGE(Tableau1[[#This Row],[STL_pg/Min]],Tableau1[[#This Row],[BLK_pg/Min]],Tableau1[[#This Row],[REB_pg/Min]]) -> 0.094246032 | BT16: =AVERAGE(Tableau1[FG%]) -> 44.610896 | BU16: =AVERAGE(Tableau1[3P%]) -> 29.90246 | BV16: =AVERAGE(Tableau1[FT%]) -> 72.024077 | BX16: Paolo Banchero | BZ16: 25.891304
A17: Kevin Durant | B17: PHX | C17: 36 | D17: 62 | E17: 33 | F17: 29 | G17: 36.5 | H17: 1649 | I17: 589 | J17: 1122 | K17: 52.7 | L17: 161 | M17: 372 | N17: 43 | O17: 304 | P17: 360 | Q17: 83.9 | R17: 25 | S17: 353 | T17: 372 | U17: 260 | V17: 192 | W17: 50 | X17: 74 | Y17: 105 | Z17: 2678 | AA17: 5 | AB17: 0 | AC17: -0.6 | AD17: 116.5 | AE17: 117.4 | AF17: -1 | AG17: 18.8 | AH17: 1.38 | AI17: 15.2 | AJ17: 1.1 | AK17: 14.7 | AL17: 8.4 | AM17: 11 | AN17: 59.8 | AO17: 64.2 | AP17: 28.3 | AQ17: 99.49 | AR17: 14.2 | AS17: 4697 | AT17: =H17/D17 -> 26.596774 | AU17: =U17/D17 -> 4.1935484 | AV17: =T17/D17 -> 6 | AW17: =R17/D17 -> 0.40322581 | AX17: =S17/D17 -> 5.6935484 | AY17: =W17/D17 -> 0.80645161 | AZ17: =X17/D17 -> 1.1935484 | BA17: =V17/D17 -> 3.0967742 | BB17: =IF(G17>0,AT17/G17,"") -> 0.72867875 | BC17: =IF(BA17>0,AU17/BA17,"") -> 1.3541667 | BD17: =IF(G17>0,AY17/G17,"") -> 0.022094565 | BE17: =IF(G17>0,AZ17/G17,"") -> 0.032699956 | BF17: =IF(G17>0,AW17/G17,"") -> 0.011047282 | BG17: =IF(G17>0,AX17/G17,"") -> 0.15598763 | BH17: =IF(G17<10,"<10 min",IF(G17<20,"10–19 min",IF(G17<30,"20–29 min",IF(G17<40,"30–39 min","40+ min")))) -> 30–39 min | BI17: =IF(C17<23,"18–22",IF(C17<28,"23–27",IF(C17<33,"28–32","33+"))) -> 33+ | BJ17: =AN17/100 -> 0.598 | BK17: =AO17/100 -> 0.642 | BL17: =J17/(MAX($J$11:$J$579)) -> 0.67712734 | BM17: =IF(AND(G17>=30,J17>=500),"Conserver","Écarter") -> Conserver | BN17: =AT17/(MAX($AT$11:$AT$579)) -> 0.81342247 | BO17: =G17*D17 -> 2263 | BP17: =IF(BO17>0,U17/BO17,"") -> 0.11489174 | BQ17: =IF(V17>0,U17/V17,0) -> 1.3541667 | BR17: =IF(G17>0,AV17/G17,"") -> 0.16438356 | BS17: =AVERAGE(Tableau1[[#This Row],[STL_pg/Min]],Tableau1[[#This Row],[BLK_pg/Min]],Tableau1[[#This Row],[REB_pg/Min]]) -> 0.073059361 | BT17: =AVERAGE(Tableau1[FG%]) -> 44.610896 | BU17: =AVERAGE(Tableau1[3P%]) -> 29.90246 | BV17: =AVERAGE(Tableau1[FT%]) -> 72.024077 | BX17: Devin Booker | BZ17: 25.6
A18: Tyrese Maxey | B18: PHI | C18: 24 | D18: 52 | E18: 20 | F18: 32 | G18: 37.7 | H18: 1368 | I18: 478 | J18: 1092 | K18: 43.7 | L18: 161 | M18: 478 | N18: 33.7 | O18: 255 | P18: 291 | Q18: 87.9 | R18: 16 | S18: 161 | T18: 172 | U18: 317 | V18: 125 | W18: 94 | X18: 21 | Y18: 114 | Z18: 2267 | AA18: 8 | AB18: 1 | AC18: -2.4 | AD18: 113.8 | AE18: 117.4 | AF18: -3.5 | AG18: 27.6 | AH18: 2.56 | AI18: 19.2 | AJ18: 0.7 | AK18: 8.7 | AL18: 4.5 | AM18: 7.5 | AN18: 51.1 | AO18: 56.2 | AP18: 29.3 | AQ18: 98.34 | AR18: 12.7 | AS18: 4024 | AT18: =H18/D18 -> 26.307692 | AU18: =U18/D18 -> 6.0961538 | AV18: =T18/D18 -> 3.3076923 | AW18: =R18/D18 -> 0.30769231 | AX18: =S18/D18 -> 3.0961538 | AY18: =W18/D18 -> 1.8076923 | AZ18: =X18/D18 -> 0.40384615 | BA18: =V18/D18 -> 2.4038462 | BB18: =IF(G18>0,AT18/G18,"") -> 0.69781677 | BC18: =IF(BA18>0,AU18/BA18,"") -> 2.536 | BD18: =IF(G18>0,AY18/G18,"") -> 0.047949398 | BE18: =IF(G18>0,AZ18/G18,"") -> 0.0107121 | BF18: =IF(G18>0,AW18/G18,"") -> 0.0081615997 | BG18: =IF(G18>0,AX18/G18,"") -> 0.082126097 | BH18: =IF(G18<10,"<10 min",IF(G18<20,"10–19 min",IF(G18<30,"20–29 min",IF(G18<40,"30–39 min","40+ min")))) -> 30–39 min | BI18: =IF(C18<23,"18–22",IF(C18<28,"23–27",IF(C18<33,"28–32","33+"))) -> 23–27 | BJ18: =AN18/100 -> 0.511 | BK18: =AO18/100 -> 0.562 | BL18: =J18/(MAX($J$11:$J$579)) -> 0.65902233 | BM18: =IF(AND(G18>=30,J18>=500),"Conserver","Écarter") -> Conserver | BN18: =AT18/(MAX($AT$11:$AT$579)) -> 0.80458133 | BO18: =G18*D18 -> 1960.4 | BP18: =IF(BO18>0,U18/BO18,"") -> 0.16170169 | BQ18: =IF(V18>0,U18/V18,0) -> 2.536 | BR18: =IF(G18>0,AV18/G18,"") -> 0.087737196 | BS18: =AVERAGE(Tableau1[[#This Row],[STL_pg/Min]],Tableau1[[#This Row],[BLK_pg/Min]],Tableau1[[#This Row],[REB_pg/Min]]) -> 0.048799565 | BT18: =AVERAGE(Tableau1[FG%]) -> 44.610896 | BU18: =AVERAGE(Tableau1[3P%]) -> 29.90246 | BV18: =AVERAGE(Tableau1[FT%]) -> 72.024077 | BX18: LaMelo Ball | BZ18: 25.191489
A19: Cade Cunningham | B19: DET | C19: 23 | D19: 70 | E19: 38 | F19: 32 | G19: 35 | H19: 1827 | I19: 686 | J19: 1456 | K19: 46.9 | L19: 147 | M19: 420 | N19: 35.6 | O19: 315 | P19: 371 | Q19: 84.6 | R19: 56 | S19: 371 | T19: 427 | U19: 637 | V19: 308 | W19: 70 | X19: 56 | Y19: 196 | Z19: 3360 | AA19: 31 | AB19: 9 | AC19: 2.5 | AD19: 115 | AE19: 112.2 | AF19: 2.8 | AG19: 40.9 | AH19: 2.06 | AI19: 25 | AJ19: 2.3 | AK19: 14.7 | AL19: 8.6 | AM19: 12.1 | AN19: 52.1 | AO19: 56.5 | AP19: 32.3 | AQ19: 101.57 | AR19: 15.2 | AS19: 5201 | AT19: =H19/D19 -> 26.1 | AU19: =U19/D19 -> 9.1 | AV19: =T19/D19 -> 6.1 | AW19: =R19/D19 -> 0.8 | AX19: =S19/D19 -> 5.3 | AY19: =W19/D19 -> 1 | AZ19: =X19/D19 -> 0.8 | BA19: =V19/D19 -> 4.4 | BB19: =IF(G19>0,AT19/G19,"") -> 0.74571429 | BC19: =IF(BA19>0,AU19/BA19,"") -> 2.0681818 | BD19: =IF(G19>0,AY19/G19,"") -> 0.028571429 | BE19: =IF(G19>0,AZ19/G19,"") -> 0.022857143 | BF19: =IF(G19>0,AW19/G19,"") -> 0.022857143 | BG19: =IF(G19>0,AX19/G19,"") -> 0.15142857 | BH19: =IF(G19<10,"<10 min",IF(G19<20,"10–19 min",IF(G19<30,"20–29 min",IF(G19<40,"30–39 min","40+ min")))) -> 30–39 min | BI19: =IF(C19<23,"18–22",IF(C19<28,"23–27",IF(C19<33,"28–32","33+"))) -> 23–27 | BJ19: =AN19/100 -> 0.521 | BK19: =AO19/100 -> 0.565 | BL19: =J19/(MAX($J$11:$J$579)) -> 0.87869644 | BM19: =IF(AND(G19>=30,J19>=500),"Conserver","Écarter") -> Conserver | BN19: =AT19/(MAX($AT$11:$AT$579)) -> 0.79822938 | BO19: =G19*D19 -> 2450 | BP19: =IF(BO19>0,U19/BO19,"") -> 0.26 | BQ19: =IF(V19>0,U19/V19,0) -> 2.0681818 | BR19: =IF(G19>0,AV19/G19,"") -> 0.17428571 | BS19: =AVERAGE(Tableau1[[#This Row],[STL_pg/Min]],Tableau1[[#This Row],[BLK_pg/Min]],Tableau1[[#This Row],[REB_pg/Min]]) -> 0.075238095 | BT19: =AVERAGE(Tableau1[FG%]) -> 44.610896 | BU19: =AVERAGE(Tableau1[3P%]) -> 29.90246 | BV19: =AVERAGE(Tableau1[FT%]) -> 72.024077 | BX19: Damian Lillard | BZ19: 24.896552
A20: Jalen Brunson | B20: NYK | C20: 28 | D20: 65 | E20: 40 | F20: 25 | G20: 35.4 | H20: 1690 | I20: 585 | J20: 1203 | K20: 48.8 | L20: 150 | M20: 397 | N20: 38.3 | O20: 371 | P20: 449 | Q20: 82.1 | R20: 26 | S20: 163 | T20: 189 | U20: 475 | V20: 163 | W20: 59 | X20: 7 | Y20: 137 | Z20: 2665 | AA20: 14 | AB20: 0 | AC20: 2.2 | AD20: 118.3 | AE20: 115.7 | AF20: 2.6 | AG20: 31.8 | AH20: 2.9 | AI20: 23.5 | AJ20: 1.2 | AK20: 7.2 | AL20: 4.2 | AM20: 8.1 | AN20: 55.1 | AO20: 60.5 | AP20: 28.9 | AQ20: 97.79 | AR20: 13.8 | AS20: 4697 | AT20: =H20/D20 -> 26 | AU20: =U20/D20 -> 7.3076923 | AV20: =T20/D20 -> 2.9076923 | AW20: =R20/D20 -> 0.4 | AX20: =S20/D20 -> 2.5076923 | AY20: =W20/D20 -> 0.90769231 | AZ20: =X20/D20 -> 0.10769231 | BA20: =V20/D20 -> 2.5076923 | BB20: =IF(G20>0,AT20/G20,"") -> 0.73446328 | BC20: =IF(BA20>0,AU20/BA20,"") -> 2.9141104 | BD20: =IF(G20>0,AY20/G20,"") -> 0.025641026 | BE20: =IF(G20>0,AZ20/G20,"") -> 0.0030421556 | BF20: =IF(G20>0,AW20/G20,"") -> 0.011299435 | BG20: =IF(G20>0,AX20/G20,"") -> 0.070838766 | BH20: =IF(G20<10,"<10 min",IF(G20<20,"10–19 min",IF(G20<30,"20–29 min",IF(G20<40,"30–39 min","40+ min")))) -> 30–39 min | BI20: =IF(C20<23,"18–22",IF(C20<28,"23–27",IF(C20<33,"28–32","33+"))) -> 28–32 | BJ20: =AN20/100 -> 0.551 | BK20: =AO20/100 -> 0.605 | BL20: =J20/(MAX($J$11:$J$579)) -> 0.72601086 | BM20: =IF(AND(G20>=30,J20>=500),"Conserver","Écarter") -> Conserver | BN20: =AT20/(MAX($AT$11:$AT$579)) -> 0.79517103 | BO20: =G20*D20 -> 2301 | BP20: =IF(BO20>0,U20/BO20,"") -> 0.20643199 | BQ20: =IF(V20>0,U20/V20,0) -> 2.9141104 | BR20: =IF(G20>0,AV20/G20,"") -> 0.082138201 | BS20: =AVERAGE(Tableau1[[#This Row],[STL_pg/Min]],Tableau1[[#This Row],[BLK_pg/Min]],Tableau1[[#This Row],[REB_pg/Min]]) -> 0.036940461 | BT20: =AVERAGE(Tableau1[FG%]) -> 44.610896 | BU20: =AVERAGE(Tableau1[3P%]) -> 29.90246 | BV20: =AVERAGE(Tableau1[FT%]) -> 72.024077 | BX20: Anthony Davis | BZ20: 24.705882
A21: Paolo Banchero | B21: ORL | C21: 22 | D21: 46 | E21: 21 | F21: 25 | G21: 34.4 | H21: 1191 | I21: 414 | J21: 911 | K21: 45.2 | L21: 87 | M21: 271 | N21: 32 | O21: 281 | P21: 386 | Q21: 72.7 | R21: 51 | S21: 294 | T21: 345 | U21: 221 | V21: 138 | W21: 37 | X21: 28 | Y21: 97 | Z21: 1992 | AA21: 11 | AB21: 0 | AC21: -0.5 | AD21: 109.1 | AE21: 109.6 | AF21: -0.6 | AG21: 26.2 | AH21: 1.61 | AI21: 15.3 | AJ21: 3.1 | AK21: 19.2 | AL21: 10.8 | AM21: 9.5 | AN21: 50 | AO21: 55.1 | AP21: 33 | AQ21: 97.29 | AR21: 15.7 | AS21: 3204 | AT21: =H21/D21 -> 25.891304 | AU21: =U21/D21 -> 4.8043478 | AV21: =T21/D21 -> 7.5 | AW21: =R21/D21 -> 1.1086957 | AX21: =S21/D21 -> 6.3913043 | AY21: =W21/D21 -> 0.80434783 | AZ21: =X21/D21 -> 0.60869565 | BA21: =V21/D21 -> 3 | BB21: =IF(G21>0,AT21/G21,"") -> 0.7526542 | BC21: =IF(BA21>0,AU21/BA21,"") -> 1.6014493 | BD21: =IF(G21>0,AY21/G21,"") -> 0.023382204 | BE21: =IF(G21>0,AZ21/G21,"") -> 0.017694641 | BF21: =IF(G21>0,AW21/G21,"") -> 0.032229525 | BG21: =IF(G21>0,AX21/G21,"") -> 0.18579373 | BH21: =IF(G21<10,"<10 min",IF(G21<20,"10–19 min",IF(G21<30,"20–29 min",IF(G21<40,"30–39 min","40+ min")))) -> 30–39 min | BI21: =IF(C21<23,"18–22",IF(C21<28,"23–27",IF(C21<33,"28–32","33+"))) -> 18–22 | BJ21: =AN21/100 -> 0.5 | BK21: =AO21/100 -> 0.551 | BL21: =J21/(MAX($J$11:$J$579)) -> 0.54978877 | BM21: =IF(AND(G21>=30,J21>=500),"Conserver","Écarter") -> Conserver | BN21: =AT21/(MAX($AT$11:$AT$579)) -> 0.79184673 | BO21: =G21*D21 -> 1582.4 | BP21: =IF(BO21>0,U21/BO21,"") -> 0.13966127 | BQ21: =IF(V21>0,U21/V21,0) -> 1.6014493 | BR21: =IF(G21>0,AV21/G21,"") -> 0.21802326 | BS21: =AVERAGE(Tableau1[[#This Row],[STL_pg/Min]],Tableau1[[#This Row],[BLK_pg/Min]],Tableau1[[#This Row],[REB_pg/Min]]) -> 0.0863667 | BT21: =AVERAGE(Tableau1[FG%]) -> 44.610896 | BU21: =AVERAGE(Tableau1[3P%]) -> 29.90246 | BV21: =AVERAGE(Tableau1[FT%]) -> 72.024077
A22: Devin Booker | B22: PHX | C22: 28 | D22: 75 | E22: 35 | F22: 40 | G22: 37.3 | H22: 1920 | I22: 653 | J22: 1418 | K22: 46.1 | L22: 180 | M22: 548 | N22: 33.2 | O22: 435 | P22: 480 | Q22: 89.4 | R22: 75 | S22: 233 | T22: 308 | U22: 533 | V22: 218 | W22: 68 | X22: 15 | Y22: 195 | Z22: 3113 | AA22: 16 | AB22: 0 | AC22: -2.4 | AD22: 115.3 | AE22: 118.5 | AF22: -3.2 | AG22: 30.1 | AH22: 2.4 | AI22: 22.4 | AJ22: 2.8 | AK22: 8 | AL22: 5.5 | AM22: 9.3 | AN22: 52.5 | AO22: 58.9 | AP22: 28.5 | AQ22: 98.72 | AR22: 12.2 | AS22: 5752 | AT22: =H22/D22 -> 25.6 | AU22: =U22/D22 -> 7.1066667 | AV22: =T22/D22 -> 4.1066667 | AW22: =R22/D22 -> 1 | AX22: =S22/D22 -> 3.1066667 | AY22: =W22/D22 -> 0.90666667 | AZ22: =X22/D22 -> 0.2 | BA22: =V22/D22 -> 2.9066667 | BB22: =IF(G22>0,AT22/G22,"") -> 0.68632708 | BC22: =IF(BA22>0,AU22/BA22,"") -> 2.4449541 | BD22: =IF(G22>0,AY22/G22,"") -> 0.024307417 | BE22: =IF(G22>0,AZ22/G22,"") -> 0.0053619303 | BF22: =IF(G22>0,AW22/G22,"") -> 0.026809651 | BG22: =IF(G22>0,AX22/G22,"") -> 0.083288651 | BH22: =IF(G22<10,"<10 min",IF(G22<20,"10–19 min",IF(G22<30,"20–29 min",IF(G22<40,"30–39 min","40+ min")))) -> 30–39 min | BI22: =IF(C22<23,"18–22",IF(C22<28,"23–27",IF(C22<33,"28–32","33+"))) -> 28–32 | BJ22: =AN22/100 -> 0.525 | BK22: =AO22/100 -> 0.589 | BL22: =J22/(MAX($J$11:$J$579)) -> 0.85576343 | BM22: =IF(AND(G22>=30,J22>=500),"Conserver","Écarter") -> Conserver | BN22: =AT22/(MAX($AT$11:$AT$579)) -> 0.78293763 | BO22: =G22*D22 -> 2797.5 | BP22: =IF(BO22>0,U22/BO22,"") -> 0.19052726 | BQ22: =IF(V22>0,U22/V22,0) -> 2.4449541 | BR22: =IF(G22>0,AV22/G22,"") -> 0.1100983 | BS22: =AVERAGE(Tableau1[[#This Row],[STL_pg/Min]],Tableau1[[#This Row],[BLK_pg/Min]],Tableau1[[#This Row],[REB_pg/Min]]) -> 0.046589217 | BT22: =AVERAGE(Tableau1[FG%]) -> 44.610896 | BU22: =AVERAGE(Tableau1[3P%]) -> 29.90246 | BV22: =AVERAGE(Tableau1[FT%]) -> 72.024077
A23: LaMelo Ball | B23: CHA | C23: 23 | D23: 47 | E23: 16 | F23: 31 | G23: 32 | H23: 1184 | I23: 404 | J23: 1001 | K23: 40.5 | L23: 179 | M23: 526 | N23: 33.9 | O23: 193 | P23: 230 | Q23: 84.3 | R23: 47 | S23: 183 | T23: 230 | U23: 348 | V23: 169 | W23: 52 | X23: 14 | Y23: 155 | Z23: 2016 | AA23: 13 | AB23: 0 | AC23: -2.8 | AD23: 112.7 | AE23: 116.5 | AF23: -3.9 | AG23: 39 | AH23: 2.07 | AI23: 21.5 | AJ23: 2.8 | AK23: 12.1 | AL23: 7.2 | AM23: 10.4 | AN23: 49.4 | AO23: 53.6 | AP23: 34.2 | AQ23: 101.33 | AR23: 12.7 | AS23: 3173 | AT23: =H23/D23 -> 25.191489 | AU23: =U23/D23 -> 7.4042553 | AV23: =T23/D23 -> 4.893617 | AW23: =R23/D23 -> 1 | AX23: =S23/D23 -> 3.893617 | AY23: =W23/D23 -> 1.106383 | AZ23: =X23/D23 -> 0.29787234 | BA23: =V23/D23 -> 3.5957447 | BB23: =IF(G23>0,AT23/G23,"") -> 0.78723404 | BC23: =IF(BA23>0,AU23/BA23,"") -> 2.0591716 | BD23: =IF(G23>0,AY23/G23,"") -> 0.034574468 | BE23: =IF(G23>0,AZ23/G23,"") -> 0.0093085106 | BF23: =IF(G23>0,AW23/G23,"") -> 0.03125 | BG23: =IF(G23>0,AX23/G23,"") -> 0.12167553 | BH23: =IF(G23<10,"<10 min",IF(G23<20,"10–19 min",IF(G23<30,"20–29 min",IF(G23<40,"30–39 min","40+ min")))) -> 30–39 min | BI23: =IF(C23<23,"18–22",IF(C23<28,"23–27",IF(C23<33,"28–32","33+"))) -> 23–27 | BJ23: =AN23/100 -> 0.494 | BK23: =AO23/100 -> 0.536 | BL23: =J23/(MAX($J$11:$J$579)) -> 0.6041038 | BM23: =IF(AND(G23>=30,J23>=500),"Conserver","Écarter") -> Conserver | BN23: =AT23/(MAX($AT$11:$AT$579)) -> 0.77044394 | BO23: =G23*D23 -> 1504 | BP23: =IF(BO23>0,U23/BO23,"") -> 0.23138298 | BQ23: =IF(V23>0,U23/V23,0) -> 2.0591716 | BR23: =IF(G23>0,AV23/G23,"") -> 0.15292553 | BS23: =AVERAGE(Tableau1[[#This Row],[STL_pg/Min]],Tableau1[[#This Row],[BLK_pg/Min]],Tableau1[[#This Row],[REB_pg/Min]]) -> 0.065602837 | BT23: =AVERAGE(Tableau1[FG%]) -> 44.610896 | BU23: =AVERAGE(Tableau1[3P%]) -> 29.90246 | BV23: =AVERAGE(Tableau1[FT%]) -> 72.024077
A24: Damian Lillard | B24: MIL | C24: 34 | D24: 58 | E24: 32 | F24: 26 | G24: 36.1 | H24: 1444 | I24: 447 | J24: 992 | K24: 44.8 | L24: 197 | M24: 522 | N24: 37.6 | O24: 360 | P24: 394 | Q24: 92.1 | R24: 29 | S24: 244 | T24: 273 | U24: 412 | V24: 162 | W24: 70 | X24: 12 | Y24: 99 | Z24: 2465 | AA24: 14 | AB24: 2 | AC24: 0.9 | AD24: 115.3 | AE24: 114.6 | AF24: 0.7 | AG24: 29.9 | AH24: 2.53 | AI24: 23.8 | AJ24: 1.4 | AK24: 10.8 | AL24: 6.3 | AM24: 9.4 | AN24: 54.7 | AO24: 62.1 | AP24: 26.9 | AQ24: 100.86 | AR24: 14.4 | AS24: 4407 | AT24: =H24/D24 -> 24.896552 | AU24: =U24/D24 -> 7.1034483 | AV24: =T24/D24 -> 4.7068966 | AW24: =R24/D24 -> 0.5 | AX24: =S24/D24 -> 4.2068966 | AY24: =W24/D24 -> 1.2068966 | AZ24: =X24/D24 -> 0.20689655 | BA24: =V24/D24 -> 2.7931034 | BB24: =IF(G24>0,AT24/G24,"") -> 0.68965517 | BC24: =IF(BA24>0,AU24/BA24,"") -> 2.5432099 | BD24: =IF(G24>0,AY24/G24,"") -> 0.033432037 | BE24: =IF(G24>0,AZ24/G24,"") -> 0.0057312064 | BF24: =IF(G24>0,AW24/G24,"") -> 0.013850416 | BG24: =IF(G24>0,AX24/G24,"") -> 0.11653453 | BH24: =IF(G24<10,"<10 min",IF(G24<20,"10–19 min",IF(G24<30,"20–29 min",IF(G24<40,"30–39 min","40+ min")))) -> 30–39 min | BI24: =IF(C24<23,"18–22",IF(C24<28,"23–27",IF(C24<33,"28–32","33+"))) -> 33+ | BJ24: =AN24/100 -> 0.547 | BK24: =AO24/100 -> 0.621 | BL24: =J24/(MAX($J$11:$J$579)) -> 0.5986723 | BM24: =IF(AND(G24>=30,J24>=500),"Conserver","Écarter") -> Conserver | BN24: =AT24/(MAX($AT$11:$AT$579)) -> 0.76142371 | BO24: =G24*D24 -> 2093.8 | BP24: =IF(BO24>0,U24/BO24,"") -> 0.19677142 | BQ24: =IF(V24>0,U24/V24,0) -> 2.5432099 | BR24: =IF(G24>0,AV24/G24,"") -> 0.13038495 | BS24: =AVERAGE(Tableau1[[#This Row],[STL_pg/Min]],Tableau1[[#This Row],[BLK_pg/Min]],Tableau1[[#This Row],[REB_pg/Min]]) -> 0.056516063 | BT24: =AVERAGE(Tableau1[FG%]) -> 44.610896 | BU24: =AVERAGE(Tableau1[3P%]) -> 29.90246 | BV24: =AVERAGE(Tableau1[FT%]) -> 72.024077
A25: Anthony Davis | B25: DAL | C25: 32 | D25: 51 | E25: 30 | F25: 21 | G25: 33.4 | H25: 1260 | I25: 469 | J25: 908 | K25: 51.6 | L25: 36 | M25: 122 | N25: 28.2 | O25: 286 | P25: 367 | Q25: 77.5 | R25: 133 | S25: 454 | T25: 592 | U25: 179 | V25: 112 | W25: 61 | X25: 112 | Y25: 97 | Z25: 2637 | AA25: 36 | AB25: 1 | AC25: 0.5 | AD25: 113.3 | AE25: 112.9 | AF25: 0.5 | AG25: 18.2 | AH25: 1.6 | AI25: 13.3 | AJ25: 8.3 | AK25: 25.4 | AL25: 17.3 | AM25: 8.3 | AN25: 53.6 | AO25: 58.8 | AP25: 30.1 | AQ25: 98.83 | AR25: 17.9 | AS25: 3515 | AT25: =H25/D25 -> 24.705882 | AU25: =U25/D25 -> 3.5098039 | AV25: =T25/D25 -> 11.607843 | AW25: =R25/D25 -> 2.6078431 | AX25: =S25/D25 -> 8.9019608 | AY25: =W25/D25 -> 1.1960784 | AZ25: =X25/D25 -> 2.1960784 | BA25: =V25/D25 -> 2.1960784 | BB25: =IF(G25>0,AT25/G25,"") -> 0.73969708 | BC25: =IF(BA25>0,AU25/BA25,"") -> 1.5982143 | BD25: =IF(G25>0,AY25/G25,"") -> 0.035810731 | BE25: =IF(G25>0,AZ25/G25,"") -> 0.065750851 | BF25: =IF(G25>0,AW25/G25,"") -> 0.078079136 | BG25: =IF(G25>0,AX25/G25,"") -> 0.26652577 | BH25: =IF(G25<10,"<10 min",IF(G25<20,"10–19 min",IF(G25<30,"20–29 min",IF(G25<40,"30–39 min","40+ min")))) -> 30–39 min | BI25: =IF(C25<23,"18–22",IF(C25<28,"23–27",IF(C25<33,"28–32","33+"))) -> 28–32 | BJ25: =AN25/100 -> 0.536 | BK25: =AO25/100 -> 0.588 | BL25: =J25/(MAX($J$11:$J$579)) -> 0.54797827 | BM25: =IF(AND(G25>=30,J25>=500),"Conserver","Écarter") -> Conserver | BN25: =AT25/(MAX($AT$11:$AT$579)) -> 0.75559238 | BO25: =G25*D25 -> 1703.4 | BP25: =IF(BO25>0,U25/BO25,"") -> 0.10508395 | BQ25: =IF(V25>0,U25/V25,0) -> 1.5982143 | BR25: =IF(G25>0,AV25/G25,"") -> 0.34754021 | BS25: =AVERAGE(Tableau1[[#This Row],[STL_pg/Min]],Tableau1[[#This Row],[BLK_pg/Min]],Tableau1[[#This Row],[REB_pg/Min]]) -> 0.1497006 | BT25: =AVERAGE(Tableau1[FG%]) -> 44.610896 | BU25: =AVERAGE(Tableau1[3P%]) -> 29.90246 | BV25: =AVERAGE(Tableau1[FT%]) -> 72.024077
A26: Kyrie Irving | B26: DAL | C26: 33 | D26: 50 | E26: 28 | F26: 22 | G26: 36.1 | H26: 1235 | I26: 445 | J26: 945 | K26: 47.3 | L26: 145 | M26: 360 | N26: 40.1 | O26: 195 | P26: 215 | Q26: 91.6 | R26: 60 | S26: 180 | T26: 240 | U26: 230 | V26: 110 | W26: 65 | X26: 25 | Y26: 100 | Z26: 2025 | AA26: 0 | AB26: 0 | AC26: 2.5 | AD26: 116.5 | AE26: 113.9 | AF26: 2.6 | AG26: 19.8 | AH26: 2.08 | AI26: 16.9 | AJ26: 3.3 | AK26: 9.3 | AL26: 6.4 | AM26: 8.1 | AN26: 54.9 | AO26: 59.4 | AP26: 26.4 | AQ26: 99.98 | AR26: 12.9 | AS26: 3768 | AT26: =H26/D26 -> 24.7 | AU26: =U26/D26 -> 4.6 | AV26: =T26/D26 -> 4.8 | AW26: =R26/D26 -> 1.2 | AX26: =S26/D26 -> 3.6 | AY26: =W26/D26 -> 1.3 | AZ26: =X26/D26 -> 0.5 | BA26: =V26/D26 -> 2.2 | BB26: =IF(G26>0,AT26/G26,"") -> 0.68421053 | BC26: =IF(BA26>0,AU26/BA26,"") -> 2.0909091 | BD26: =IF(G26>0,AY26/G26,"") -> 0.03601108 | BE26: =IF(G26>0,AZ26/G26,"") -> 0.013850416 | BF26: =IF(G26>0,AW26/G26,"") -> 0.033240997 | BG26: =IF(G26>0,AX26/G26,"") -> 0.099722992 | BH26: =IF(G26<10,"<10 min",IF(G26<20,"10–19 min",IF(G26<30,"20–29 min",IF(G26<40,"30–39 min","40+ min")))) -> 30–39 min | BI26: =IF(C26<23,"18–22",IF(C26<28,"23–27",IF(C26<33,"28–32","33+"))) -> 33+ | BJ26: =AN26/100 -> 0.549 | BK26: =AO26/100 -> 0.594 | BL26: =J26/(MAX($J$11:$J$579)) -> 0.57030779 | BM26: =IF(AND(G26>=30,J26>=500),"Conserver","Écarter") -> Conserver | BN26: =AT26/(MAX($AT$11:$AT$579)) -> 0.75541247 | BO26: =G26*D26 -> 1805 | BP26: =IF(BO26>0,U26/BO26,"") -> 0.12742382 | BQ26: =IF(V26>0,U26/V26,0) -> 2.0909091 | BR26: =IF(G26>0,AV26/G26,"") -> 0.13296399 | BS26: =AVERAGE(Tableau1[[#This Row],[STL_pg/Min]],Tableau1[[#This Row],[BLK_pg/Min]],Tableau1[[#This Row],[REB_pg/Min]]) -> 0.060941828 | BT26: =AVERAGE(Tableau1[FG%]) -> 44.610896 | BU26: =AVERAGE(Tableau1[3P%]) -> 29.90246 | BV26: =AVERAGE(Tableau1[FT%]) -> 72.024077
A27: Zion Williamson | B27: NOP | C27: 24 | D27: 30 | E27: 10 | F27: 20 | G27: 28.6 | H27: 738 | I27: 288 | J27: 507 | K27: 56.7 | L27: 3 | M27: 12 | N27: 23.1 | O27: 159 | P27: 240 | Q27: 65.6 | R27: 75 | S27: 141 | T27: 216 | U27: 159 | V27: 90 | W27: 36 | X27: 27 | Y27: 81 | Z27: 1338 | AA27: 8 | AB27: 2 | AC27: -1.4 | AD27: 113.7 | AE27: 115.5 | AF27: -1.8 | AG27: 32.5 | AH27: 1.77 | AI27: 18.5 | AJ27: 8 | AK27: 15.2 | AL27: 11.6 | AM27: 10.5 | AN27: 57 | AO27: 60 | AP27: 32.5 | AQ27: 103.3 | AR27: 16.7 | AS27: 1841 | AT27: =H27/D27 -> 24.6 | AU27: =U27/D27 -> 5.3 | AV27: =T27/D27 -> 7.2 | AW27: =R27/D27 -> 2.5 | AX27: =S27/D27 -> 4.7 | AY27: =W27/D27 -> 1.2 | AZ27: =X27/D27 -> 0.9 | BA27: =V27/D27 -> 3 | BB27: =IF(G27>0,AT27/G27,"") -> 0.86013986 | BC27: =IF(BA27>0,AU27/BA27,"") -> 1.7666667 | BD27: =IF(G27>0,AY27/G27,"") -> 0.041958042 | BE27: =IF(G27>0,AZ27/G27,"") -> 0.031468531 | BF27: =IF(G27>0,AW27/G27,"") -> 0.087412587 | BG27: =IF(G27>0,AX27/G27,"") -> 0.16433566 | BH27: =IF(G27<10,"<10 min",IF(G27<20,"10–19 min",IF(G27<30,"20–29 min",IF(G27<40,"30–39 min","40+ min")))) -> 20–29 min | BI27: =IF(C27<23,"18–22",IF(C27<28,"23–27",IF(C27<33,"28–32","33+"))) -> 23–27 | BJ27: =AN27/100 -> 0.57 | BK27: =AO27/100 -> 0.6 | BL27: =J27/(MAX($J$11:$J$579)) -> 0.30597465 | BM27: =IF(AND(G27>=30,J27>=500),"Conserver","Écarter") -> Écarter | BN27: =AT27/(MAX($AT$11:$AT$579)) -> 0.75235412 | BO27: =G27*D27 -> 858 | BP27: =IF(BO27>0,U27/BO27,"") -> 0.18531469 | BQ27: =IF(V27>0,U27/V27,0) -> 1.7666667 | BR27: =IF(G27>0,AV27/G27,"") -> 0.25174825 | BS27: =AVERAGE(Tableau1[[#This Row],[STL_pg/Min]],Tableau1[[#This Row],[BLK_pg/Min]],Tableau1[[#This Row],[REB_pg/Min]]) -> 0.10839161 | BT27: =AVERAGE(Tableau1[FG%]) -> 44.610896 | BU27: =AVERAGE(Tableau1[3P%]) -> 29.90246 | BV27: =AVERAGE(Tableau1[FT%]) -> 72.024077
